Workbook
Name Act_Names: [1]Lookups!$A$7:$B$21
Name Analysis: [1]!Analysis4[#Data]
Name AUTHORITATIVEREFERENCE: #REF!
Name Capabilities: #REF!
Name Capabilities: #REF!
Name CapabilityIDs_nr: [2]!CapabilityID_tbl[CapabilityID]
Name DoahAmanda: '[3]Doah and Amanda'!$A$2:$F$28
Name Effectiveness: #REF!
Name ETSNEXT_Deloite_Digital_Usability_Report__September_2016: #REF!
Name HollyTammyAlexDotti: '[4]Holly, Tammy, Alex, and Dotti'!$A$2:$F$28
Name HRJobGroup: [5]!HRJobTable[[#All],[Group]:[Occupation Group]]
Name HRJobSeries: [5]!HRJobTable[[#All],[Occupation Series Code]:[Occupation Series Label]]
Name HRJobTitle: [5]!HRJobTable[[#All],[Occupation Title Code]:[Occupation Title Label]]
Name LookupByCapRef: #REF!
Name LookupByCapRef: #REF!
Name Priority: '[6]Cross-cut Functs'!$Q$7:$Q$10
Name Service_Activity_ID_Names: [2]!Service_Activities_tbl[ServiceActivityName]
Name ServiceActivities: 'FFM-Functions-Activities'!$1:$1048576
Name ServiceFunctions: #REF!
Name SteveAngie: '[4]Steve and Angie'!$A$2:$F$28

Sheet Cover Page
A1: Draft/Pre-Decisional
A12: Financial Management (FM) Solution/Service Definition Template
A16: As of: May 26, 2021
G19: Draft/Pre-Decisional
G20: This RFI (Request for Information) is issued solely for market research and planning purposes. The RFI does not constitute a solicitation or a commitment to a particular acquisition strategy. The RFI is intended to get industry feedback on the vision for the FM QSMO Marketplace, which includes core financial system and other financial management services and solutions. Nothing in this document should be construed as a final government decision upon which industry should take action and the RFI is subject to change. Treasury is not seeking proposals at this time and will not consider unsolicited proposals provided in response to the RFI. All information received in response to the RFI that is marked as proprietary will be handled accordingly. Responses to this notice are not offers and cannot be accepted by the Government to form a binding contract. Responders are solely responsible for all expenses associated with responding to the RFI.

Sheet Overview
B1: Draft/Pre-Decisional
B2: This RFI (Request for Information) is issued solely for market research and planning purposes. The RFI does not constitute a solicitation or a commitment to a particular acquisition strategy. The RFI is intended to get industry feedback on the vision for the FM QSMO Marketplace, which includes core financial system and other financial management services and solutions. Nothing in this document should be construed as a final government decision upon which industry should take action and the RFI is subject to change. Treasury is not seeking proposals at this time and will not consider unsolicited proposals provided in response to the RFI. All information received in response to the RFI that is marked as proprietary will be handled accordingly. Responses to this notice are not offers and cannot be accepted by the Government to form a binding contract. Responders are solely responsible for all expenses associated with responding to the RFI.
A3: Overview
A4: ='Cover Page'!A16 -> As of: May 26, 2021
A5: FM Solution/Service Definition Template
A6: Workbook Tab Name | B6: Description
A7: Overview | B7: This tab lists each workbook tab and provides an explanation of the tab's contents
A8: Solution/Service Definition Tabs:
A9: FM Sol-Serv Def Template FM Sol-Serv Def Example - SaaS FM Sol-Serv Def Example - PaaS FM Sol-Serv Def Example - Audit
A10: Objective | B10: These tabs provide the template and examples of FM solution/service package definitions indicating what components are included and excluded from an FM solution/service package.
A11: Provider Name | B11: Identifies the name of the provider of the FM solution/service
A12: FM Solution/Service Package Name | B12: Identifies the name of the FM solution/service offering. The term "package" is used because a single provider may offer multiple variations of their FM solution/service offering (e.g., Core FS using commercial IaaS subservices and Core FS using classified government cloud IaaS subservices).
A13: FM Solution/Service Package Short Description | B13: Provides a short description of the FM solution/service offering, including the general scope and the intended use by the Service Customer
A14: FFM Functions: Activities | B14: For each FFM Function/Activity listed, indicates which components are included in (enabled or performed) or excluded from the FM solution/service package. This is referred to as the "Business View" of the FM solution/service package being offered.
A15: Service Delivery Layers and Towers: Sub-Towers | B15: For each Sub-Tower within a Tower within a Service Delivery Layer, indicates which components are included in or excluded from the FM solution/service package. This is referred to as the "Asset View" of the FM solution/service package being offered.
A16: Service Delivery Resources and Cost Pools | B16: For each Cost Pool within a Service Delivery Resource category, indicates which components are included in or excluded from the FM solution/service package. Note that "external labor" and "outside service" refer to sub-contractors or sub-services the Service Provider manages and integrates into the FM solution/service offering or to which the Service Provider needs access.
A17: Indicator | B17: N/A = None of the components are applicable to delivering the service or using the solution INCL = All applicable components are included in delivering the service or using the solution EXCL/R* = Components are not included in solution/service offering, but are required when delivering the service or using the solution EXCL/O* = Components are not included in solution/service offering, but can be optional when delivering the service or using the solution PRTL/NA* = Some components are not included in solution/service offering because they are not applicable when delivering the service or using the solution PRTL/R* = Some components are not included in solution/service offering, but are required when delivering the service or using the solution PRTL/O* = Some components are not included in solution/service offering, but can be optional when delivering the service or using the solution * = Explanation required e.g., the specific components or resources excluded and/or to be provided by Service Customer (e.g., GFE)
A18: Additional Explanation | B18: Further explanation of what is included or excluded in an FM solution/service package and expectations of assets to be provided by Service Customers
A19: Additional Tabs in this Workbook are provided for reference purposes only.
A20: FFM-Functions-Activities Tab
A21: Objective | B21: This tab provides a list and description of FFM Functions and Activities for reference purposes
A22: ServiceFunctionID | B22: This column provides the unique identifier for the Service Function.
A23: ServiceFunctionName | B23: This column provides the short name for the FIBF Service Function.
A24: Service Activity ID | B24: This column provides the unique identifier for the Service Activity.
A25: Service Activity Name | B25: This column provides the short name for the FIBF Service Activity.
A26: Service Activity Description | B26: This column provides a description of the FIBF Service Activity.
A27: Serv Delivery Layers-Resources Tab
A28: Objective | B28: This tab includes a high-level graphic and description of Service Delivery Layers and Service Delivery Resources for reference purposes.
A29: Towers-SubTowers Tab
A30: Objective | B30: This tab provides a high-level list and description of the commercial TBM Towers/Sub-Towers plus government-defined extensions to commercial TBM Towers/Sub-Towers for reference purposes. The government-defined extensions are used to fully account for other anticipated service delivery components and costs not explicitly addressed in the commercial TBM Tower/Sub-Tower descriptions.
A31: Cost Pools-SubCost PoolsTab
A32: Objective | B32: This tab provides a high-level list and description of the TBM Cost Pools and Sub-Cost Pools
A33: Service Components List Tab
A34: Objective | B34: Provides a detailed list of service components that can be filtered by Service Delivery Layer, Towers/Sub-Towers, Service Delivery Resources, and Cost Pools/Sub-Cost Pools. This list can be used as a checklist to ensure all service-solution components have been considered when defining what is included/excluded in a service package or to further understand which components should be accounted for in which category (Service Delivery Layer, Service Delivery Resources, Towers/Sub-Towers, and Cost Pools/Sub-Cost Pools).
A35: ITIL Tab
A36: Objective | B36: This tab provides a list of the Information Technology Infrastructure Library (ITIL) Practices referenced in the Service Components List tab.

Sheet FM Sol-Serv Def Template
B1: Draft/Pre-Decisional
B2: This RFI (Request for Information) is issued solely for market research and planning purposes. The RFI does not constitute a solicitation or a commitment to a particular acquisition strategy. The RFI is intended to get industry feedback on the vision for the FM QSMO Marketplace, which includes core financial system and other financial management services and solutions. Nothing in this document should be construed as a final government decision upon which industry should take action and the RFI is subject to change. Treasury is not seeking proposals at this time and will not consider unsolicited proposals provided in response to the RFI. All information received in response to the RFI that is marked as proprietary will be handled accordingly. Responses to this notice are not offers and cannot be accepted by the Government to form a binding contract. Responders are solely responsible for all expenses associated with responding to the RFI.
A3: FM Solution/Service Definition Template
A4: ='Cover Page'!A16 -> As of: May 26, 2021
A6: Provider Name:
A7: FM Solution/Service Package Name:
A8: FM Solution/Service Package Short Description:
A9: Business View | B9: Draft/Pre-Decisional
A10: FFM Functions: Activities | B10: Indicator | C10: Additional Explanation
A11: =CONCATENATE('FFM-Functions-Activities'!B3,": ",'FFM-Functions-Activities'!D3) -> Budget Execution: Budget Setup and Maintenance
A12: =CONCATENATE('FFM-Functions-Activities'!B4,": ",'FFM-Functions-Activities'!D4) -> Budget Execution: Fund Allocation and Control
A13: =CONCATENATE('FFM-Functions-Activities'!B5,": ",'FFM-Functions-Activities'!D5) -> Budget Execution: Budgetary Reporting
A14: =CONCATENATE('FFM-Functions-Activities'!B6,": ",'FFM-Functions-Activities'!D6) -> Financial Asset Information Management: Financial Asset Information Processing - Property, Plant, and Equipment
A15: =CONCATENATE('FFM-Functions-Activities'!B7,": ",'FFM-Functions-Activities'!D7) -> Financial Asset Information Management: Financial Asset Information Processing - Loans
A16: =CONCATENATE('FFM-Functions-Activities'!B8,": ",'FFM-Functions-Activities'!D8) -> Financial Asset Information Management: Financial Asset Information Processing - Heritage Assets and Stewardship Land
A17: =CONCATENATE('FFM-Functions-Activities'!B9,": ",'FFM-Functions-Activities'!D9) -> Financial Asset Information Management: Financial Asset Information Processing - Federal Oil and Gas Resources
A18: =CONCATENATE('FFM-Functions-Activities'!B10,": ",'FFM-Functions-Activities'!D10) -> Financial Asset Information Management: Financial Asset Information Processing - Other Federal Assets
A19: =CONCATENATE('FFM-Functions-Activities'!B11,": ",'FFM-Functions-Activities'!D11) -> Financial Asset Information Management: Financial Asset Information Reporting
A20: =CONCATENATE('FFM-Functions-Activities'!B12,": ",'FFM-Functions-Activities'!D12) -> Payable Management: Payee Setup and Maintenance
A21: =CONCATENATE('FFM-Functions-Activities'!B13,": ",'FFM-Functions-Activities'!D13) -> Payable Management: Obligation Management
A22: =CONCATENATE('FFM-Functions-Activities'!B14,": ",'FFM-Functions-Activities'!D14) -> Payable Management: Payment Processing - Intragovernmental Payments
... A64: =CONCATENATE('FFM-Functions-Activities'!B56,": ",'FFM-Functions-Activities'!D56) -> Financial / Performance Reporting: Internal Control/Compliance Reviews
A66: Asset View
A67: Service Delivery Resources: | B67: Technology | H67: Workforce | J67: Advisory | L67: Additional Explanation
A68: Cost Pools: | B68: Facilities | C68: Telecom-Network | D68: Hardware | E68: Software | F68: Internal Services | G68: Outside Services | H68: Internal Labor | I68: External Labor | J68: Internal Labor | K68: External Labor
A69: Service Delivery Layers and Towers: Sub-Towers
A70: SL0: Service Delivery Management
A71: IT Management: IT Management and Strategic Planning
A72: IT Management: Enterprise Architecture
A73: IT Management: IT Finance
A74: IT Management: IT Vendor Management
A75: IT Management: IT Human Capital Management
A76: IT Management: IT Personnel Travel
A77: Delivery: IT Service Management
A78: Delivery: Program, Product & Project Management
A79: Delivery: Client Management
A80: Delivery: Operations Center
... A145: Compliance & Controls: Internal Control & Audit

Sheet FM Sol-Serv Def Example - SaaS
B1: Draft/Pre-Decisional
B2: This RFI (Request for Information) is issued solely for market research and planning purposes. The RFI does not constitute a solicitation or a commitment to a particular acquisition strategy. The RFI is intended to get industry feedback on the vision for the FM QSMO Marketplace, which includes core financial system and other financial management services and solutions. Nothing in this document should be construed as a final government decision upon which industry should take action and the RFI is subject to change. Treasury is not seeking proposals at this time and will not consider unsolicited proposals provided in response to the RFI. All information received in response to the RFI that is marked as proprietary will be handled accordingly. Responses to this notice are not offers and cannot be accepted by the Government to form a binding contract. Responders are solely responsible for all expenses associated with responding to the RFI.
A3: FM Solution/Service Definition Example - Core FS SaaS
A4: ='Cover Page'!A16 -> As of: May 26, 2021
A6: Provider Name: | B6: ABC Company
A7: FM Solution/Service Package Name: | B7: ABC Core FS Software-as-a-Service (SaaS)
A8: FM Solution/Service Package Short Description: | B8: ABC Core FS SaaS offers capabilities that enable customers to perform all FIBF FFM Functions, is fully compliant with Core FS Baseline Solution standards, and provides a full set of technical and operational support services, including Tier 1 service desk support.
A9: Business View
A10: FFM Functions: Activities | B10: Indicator | C10: Additional Explanation
A11: =CONCATENATE('FFM-Functions-Activities'!B3,": ",'FFM-Functions-Activities'!D3) -> Budget Execution: Budget Setup and Maintenance | B11: INCL
A12: =CONCATENATE('FFM-Functions-Activities'!B4,": ",'FFM-Functions-Activities'!D4) -> Budget Execution: Fund Allocation and Control | B12: INCL | C12: The required standard BIE with other lines of business (Functional Areas) is provided to automate execution of funds availability checks
A13: =CONCATENATE('FFM-Functions-Activities'!B5,": ",'FFM-Functions-Activities'!D5) -> Budget Execution: Budgetary Reporting | B13: INCL | C13: The required standard set of FM reports/information extracts are provided; agency-specific reports/information extracts can be developed and provided for an additional cost.
A14: =CONCATENATE('FFM-Functions-Activities'!B6,": ",'FFM-Functions-Activities'!D6) -> Financial Asset Information Management: Financial Asset Information Processing - Property, Plant, and Equipment | B14: INCL | C14: Financial asset information will be recorded using a journal voucher.
A15: =CONCATENATE('FFM-Functions-Activities'!B7,": ",'FFM-Functions-Activities'!D7) -> Financial Asset Information Management: Financial Asset Information Processing - Loans | B15: INCL | C15: Financial asset information will be recorded using a journal voucher.
A16: =CONCATENATE('FFM-Functions-Activities'!B8,": ",'FFM-Functions-Activities'!D8) -> Financial Asset Information Management: Financial Asset Information Processing - Heritage Assets and Stewardship Land | B16: INCL | C16: Financial asset information will be recorded using a journal voucher.
A17: =CONCATENATE('FFM-Functions-Activities'!B9,": ",'FFM-Functions-Activities'!D9) -> Financial Asset Information Management: Financial Asset Information Processing - Federal Oil and Gas Resources | B17: INCL | C17: Financial asset information will be recorded using a journal voucher.
A18: =CONCATENATE('FFM-Functions-Activities'!B10,": ",'FFM-Functions-Activities'!D10) -> Financial Asset Information Management: Financial Asset Information Processing - Other Federal Assets | B18: INCL | C18: Financial asset information will be recorded using a journal voucher.
A19: =CONCATENATE('FFM-Functions-Activities'!B11,": ",'FFM-Functions-Activities'!D11) -> Financial Asset Information Management: Financial Asset Information Reporting | B19: INCL | C19: The required standard set of FM reports/information extracts are provided; agency-specific reports/information extracts can be developed and provided for an additional cost.
A20: =CONCATENATE('FFM-Functions-Activities'!B12,": ",'FFM-Functions-Activities'!D12) -> Payable Management: Payee Setup and Maintenance | B20: INCL | C20: The required standard BIE with SAM.gov is provided; agency-specific BIE extensions can be developed and provided for an additional cost.
A21: =CONCATENATE('FFM-Functions-Activities'!B13,": ",'FFM-Functions-Activities'!D13) -> Payable Management: Obligation Management | B21: INCL | C21: The required standard BIEs with other lines of business (Functional Areas) are provided; agency-specific BIE extensions can be developed and provided for an additional cost.
A22: =CONCATENATE('FFM-Functions-Activities'!B14,": ",'FFM-Functions-Activities'!D14) -> Payable Management: Payment Processing - Intragovernmental Payments | B22: INCL | C22: The required standard BIE with G-Invoicing is provided; agency-specific BIE extensions can be developed and provided for an additional cost.
A23: =CONCATENATE('FFM-Functions-Activities'!B15,": ",'FFM-Functions-Activities'!D15) -> Payable Management: Payment Processing - Payroll Payments | B23: INCL | C23: The required standard BIEs for payroll are provided; agency-specific BIE extensions can be developed and provided for an additional cost.
A24: =CONCATENATE('FFM-Functions-Activities'!B16,": ",'FFM-Functions-Activities'!D16) -> Payable Management: Payment Processing - Travel Temporary Duty (TDY) and Local Payments | B24: INCL | C24: The required standard BIE with the TRT Functional Area is provided; agency-specific BIE extensions can be developed and provided for an additional cost.
A25: =CONCATENATE('FFM-Functions-Activities'!B17,": ",'FFM-Functions-Activities'!D17) -> Payable Management: Payment Processing - Travel PCS Payments | B25: INCL
A26: =CONCATENATE('FFM-Functions-Activities'!B18,": ",'FFM-Functions-Activities'!D18) -> Payable Management: Payment Processing - Commercial Payments | B26: INCL | C26: The required standard BIE with the ACQ Functional Area is provided; agency-specific BIE extensions and additional BIEs can be developed and provided for an additional cost.
A27: =CONCATENATE('FFM-Functions-Activities'!B19,": ",'FFM-Functions-Activities'!D19) -> Payable Management: Payment Processing - Grant Payments | B27: INCL | C27: The required standard BIE with the GRM Functional Area is provided; agency-specific BIE extensions can be developed and provided for an additional cost.
A28: =CONCATENATE('FFM-Functions-Activities'!B20,": ",'FFM-Functions-Activities'!D20) -> Payable Management: Payment Processing - Loan Payments | B28: INCL
A29: =CONCATENATE('FFM-Functions-Activities'!B21,": ",'FFM-Functions-Activities'!D21) -> Payable Management: Payment Processing - Other Payments (Foreign and Miscellaneous Payments) | B29: INCL
A30: =CONCATENATE('FFM-Functions-Activities'!B22,": ",'FFM-Functions-Activities'!D22) -> Payable Management: Payment Disbursement | B30: INCL
A31: =CONCATENATE('FFM-Functions-Activities'!B23,": ",'FFM-Functions-Activities'!D23) -> Payable Management: Payment Confirmation and Issue Resolution | B31: INCL
A32: =CONCATENATE('FFM-Functions-Activities'!B24,": ",'FFM-Functions-Activities'!D24) -> Payable Management: Payment Reporting | B32: INCL | C32: The required standard set of FM reports/information extracts are provided; agency-specific reports/information extracts can be developed and provided for an additional cost.
A33: =CONCATENATE('FFM-Functions-Activities'!B25,": ",'FFM-Functions-Activities'!D25) -> Revenue Management: Revenue Processing | B33: INCL
A34: =CONCATENATE('FFM-Functions-Activities'!B26,": ",'FFM-Functions-Activities'!D26) -> Revenue Management: Revenue Reporting | B34: INCL | C34: A standard set of FM reports/information extracts are provided; agency-specific reports/information extracts can be developed and provided for an additional cost.
A35: =CONCATENATE('FFM-Functions-Activities'!B27,": ",'FFM-Functions-Activities'!D27) -> Reimbursable Management: Reimbursable Agreement Setup and Maintenance | B35: INCL
A36: =CONCATENATE('FFM-Functions-Activities'!B28,": ",'FFM-Functions-Activities'!D28) -> Reimbursable Management: Reimbursable Invoicing | B36: INCL | C36: The required standard BIE with G-Invoicing is provided; agency-specific BIE extensions can be developed and provided for an additional cost.
A37: =CONCATENATE('FFM-Functions-Activities'!B29,": ",'FFM-Functions-Activities'!D29) -> Reimbursable Management: Reimbursable Receipt Processing | B37: INCL | C37: The required standard BIE with G-Invoicing is provided; agency-specific BIE extensions can be developed and provided for an additional cost.
A38: =CONCATENATE('FFM-Functions-Activities'!B30,": ",'FFM-Functions-Activities'!D30) -> Reimbursable Management: Reimbursable Reconciliation | B38: INCL
A39: =CONCATENATE('FFM-Functions-Activities'!B31,": ",'FFM-Functions-Activities'!D31) -> Reimbursable Management: Reimbursable Closeout | B39: INCL
A40: =CONCATENATE('FFM-Functions-Activities'!B32,": ",'FFM-Functions-Activities'!D32) -> Reimbursable Management: Reimbursable Reporting | B40: INCL | C40: A standard set of FM reports/information extracts are provided; agency-specific reports/information extracts can be developed and provided for an additional cost.
A41: =CONCATENATE('FFM-Functions-Activities'!B33,": ",'FFM-Functions-Activities'!D33) -> Receivable and Collection Management: Payer Setup and Maintenance | B41: INCL
...

Sheet FM Sol-Serv Def Example - PaaS
B1: Draft/Pre-Decisional
B2: This RFI (Request for Information) is issued solely for market research and planning purposes. The RFI does not constitute a solicitation or a commitment to a particular acquisition strategy. The RFI is intended to get industry feedback on the vision for the FM QSMO Marketplace, which includes core financial system and other financial management services and solutions. Nothing in this document should be construed as a final government decision upon which industry should take action and the RFI is subject to change. Treasury is not seeking proposals at this time and will not consider unsolicited proposals provided in response to the RFI. All information received in response to the RFI that is marked as proprietary will be handled accordingly. Responses to this notice are not offers and cannot be accepted by the Government to form a binding contract. Responders are solely responsible for all expenses associated with responding to the RFI.
A3: FM Solution/Service Definition Example - Core FS PaaS
A4: ='Cover Page'!A16 -> As of: May 26, 2021
A6: Provider Name: | B6: XYZ Company
A7: FM Solution/Service Package Name: | B7: XYZ Core FS Platform-as-a-Service (PaaS)
A8: FM Solution/Service Package Short Description: | B8: XYZ Core FS PaaS offers capabilities that enable customers to perform all FIBF FFM Functions and is fully compliant with Core FS Baseline Solution standards.
A9: Business View
A10: FFM Functions: Activities | B10: Indicator | C10: Additional Explanation
A11: =CONCATENATE('FFM-Functions-Activities'!B3,": ",'FFM-Functions-Activities'!D3) -> Budget Execution: Budget Setup and Maintenance | B11: INCL
A12: =CONCATENATE('FFM-Functions-Activities'!B4,": ",'FFM-Functions-Activities'!D4) -> Budget Execution: Fund Allocation and Control | B12: INCL | C12: The required standard BIE with other lines of business (Functional Areas) is provided to automate execution of funds availability checks
A13: =CONCATENATE('FFM-Functions-Activities'!B5,": ",'FFM-Functions-Activities'!D5) -> Budget Execution: Budgetary Reporting | B13: INCL | C13: The required standard set of FM reports/information extracts are provided
A14: =CONCATENATE('FFM-Functions-Activities'!B6,": ",'FFM-Functions-Activities'!D6) -> Financial Asset Information Management: Financial Asset Information Processing - Property, Plant, and Equipment | B14: INCL | C14: Financial asset information will be recorded using a journal voucher.
A15: =CONCATENATE('FFM-Functions-Activities'!B7,": ",'FFM-Functions-Activities'!D7) -> Financial Asset Information Management: Financial Asset Information Processing - Loans | B15: INCL | C15: Financial asset information will be recorded using a journal voucher.
A16: =CONCATENATE('FFM-Functions-Activities'!B8,": ",'FFM-Functions-Activities'!D8) -> Financial Asset Information Management: Financial Asset Information Processing - Heritage Assets and Stewardship Land | B16: INCL | C16: Financial asset information will be recorded using a journal voucher.
A17: =CONCATENATE('FFM-Functions-Activities'!B9,": ",'FFM-Functions-Activities'!D9) -> Financial Asset Information Management: Financial Asset Information Processing - Federal Oil and Gas Resources | B17: INCL | C17: Financial asset information will be recorded using a journal voucher.
A18: =CONCATENATE('FFM-Functions-Activities'!B10,": ",'FFM-Functions-Activities'!D10) -> Financial Asset Information Management: Financial Asset Information Processing - Other Federal Assets | B18: INCL | C18: Financial asset information will be recorded using a journal voucher.
A19: =CONCATENATE('FFM-Functions-Activities'!B11,": ",'FFM-Functions-Activities'!D11) -> Financial Asset Information Management: Financial Asset Information Reporting | B19: INCL | C19: The required standard set of FM reports/information extracts are provided
A20: =CONCATENATE('FFM-Functions-Activities'!B12,": ",'FFM-Functions-Activities'!D12) -> Payable Management: Payee Setup and Maintenance | B20: INCL | C20: The required standard BIE with SAM.gov is provided
A21: =CONCATENATE('FFM-Functions-Activities'!B13,": ",'FFM-Functions-Activities'!D13) -> Payable Management: Obligation Management | B21: INCL | C21: The required standard BIEs with other lines of business (Functional Areas) are provided.
A22: =CONCATENATE('FFM-Functions-Activities'!B14,": ",'FFM-Functions-Activities'!D14) -> Payable Management: Payment Processing - Intragovernmental Payments | B22: INCL | C22: The required standard BIE with G-Invoicing is provided.
A23: =CONCATENATE('FFM-Functions-Activities'!B15,": ",'FFM-Functions-Activities'!D15) -> Payable Management: Payment Processing - Payroll Payments | B23: INCL | C23: The required standard BIEs for payroll are provided.
A24: =CONCATENATE('FFM-Functions-Activities'!B16,": ",'FFM-Functions-Activities'!D16) -> Payable Management: Payment Processing - Travel Temporary Duty (TDY) and Local Payments | B24: INCL | C24: The required standard BIE with the TRT Functional Area is provided.
A25: =CONCATENATE('FFM-Functions-Activities'!B17,": ",'FFM-Functions-Activities'!D17) -> Payable Management: Payment Processing - Travel PCS Payments | B25: INCL
A26: =CONCATENATE('FFM-Functions-Activities'!B18,": ",'FFM-Functions-Activities'!D18) -> Payable Management: Payment Processing - Commercial Payments | B26: INCL | C26: The required standard BIE with the ACQ Functional Area is provided.
A27: =CONCATENATE('FFM-Functions-Activities'!B19,": ",'FFM-Functions-Activities'!D19) -> Payable Management: Payment Processing - Grant Payments | B27: INCL | C27: The required standard BIE with the GRM Functional Area is provided.
A28: =CONCATENATE('FFM-Functions-Activities'!B20,": ",'FFM-Functions-Activities'!D20) -> Payable Management: Payment Processing - Loan Payments | B28: INCL
A29: =CONCATENATE('FFM-Functions-Activities'!B21,": ",'FFM-Functions-Activities'!D21) -> Payable Management: Payment Processing - Other Payments (Foreign and Miscellaneous Payments) | B29: INCL
A30: =CONCATENATE('FFM-Functions-Activities'!B22,": ",'FFM-Functions-Activities'!D22) -> Payable Management: Payment Disbursement | B30: INCL
A31: =CONCATENATE('FFM-Functions-Activities'!B23,": ",'FFM-Functions-Activities'!D23) -> Payable Management: Payment Confirmation and Issue Resolution | B31: INCL
A32: =CONCATENATE('FFM-Functions-Activities'!B24,": ",'FFM-Functions-Activities'!D24) -> Payable Management: Payment Reporting | B32: INCL | C32: The required standard set of FM reports/information extracts are provided.
A33: =CONCATENATE('FFM-Functions-Activities'!B25,": ",'FFM-Functions-Activities'!D25) -> Revenue Management: Revenue Processing | B33: INCL
A34: =CONCATENATE('FFM-Functions-Activities'!B26,": ",'FFM-Functions-Activities'!D26) -> Revenue Management: Revenue Reporting | B34: INCL | C34: A standard set of FM reports/information extracts are provided.
A35: =CONCATENATE('FFM-Functions-Activities'!B27,": ",'FFM-Functions-Activities'!D27) -> Reimbursable Management: Reimbursable Agreement Setup and Maintenance | B35: INCL
A36: =CONCATENATE('FFM-Functions-Activities'!B28,": ",'FFM-Functions-Activities'!D28) -> Reimbursable Management: Reimbursable Invoicing | B36: INCL | C36: The required standard BIE with G-Invoicing is provided.
A37: =CONCATENATE('FFM-Functions-Activities'!B29,": ",'FFM-Functions-Activities'!D29) -> Reimbursable Management: Reimbursable Receipt Processing | B37: INCL | C37: The required standard BIE with G-Invoicing is provided.
A38: =CONCATENATE('FFM-Functions-Activities'!B30,": ",'FFM-Functions-Activities'!D30) -> Reimbursable Management: Reimbursable Reconciliation | B38: INCL
A39: =CONCATENATE('FFM-Functions-Activities'!B31,": ",'FFM-Functions-Activities'!D31) -> Reimbursable Management: Reimbursable Closeout | B39: INCL
A40: =CONCATENATE('FFM-Functions-Activities'!B32,": ",'FFM-Functions-Activities'!D32) -> Reimbursable Management: Reimbursable Reporting | B40: INCL | C40: A standard set of FM reports/information extracts are provided.
A41: =CONCATENATE('FFM-Functions-Activities'!B33,": ",'FFM-Functions-Activities'!D33) -> Receivable and Collection Management: Payer Setup and Maintenance | B41: INCL
...

Sheet FM Sol-Serv Def Example-Audit
B1: Draft/Pre-Decisional
B2: This RFI (Request for Information) is issued solely for market research and planning purposes. The RFI does not constitute a solicitation or a commitment to a particular acquisition strategy. The RFI is intended to get industry feedback on the vision for the FM QSMO Marketplace, which includes core financial system and other financial management services and solutions. Nothing in this document should be construed as a final government decision upon which industry should take action and the RFI is subject to change. Treasury is not seeking proposals at this time and will not consider unsolicited proposals provided in response to the RFI. All information received in response to the RFI that is marked as proprietary will be handled accordingly. Responses to this notice are not offers and cannot be accepted by the Government to form a binding contract. Responders are solely responsible for all expenses associated with responding to the RFI.
A3: FM Solution/Service Definition Example - Audit Services
A4: ='Cover Page'!A16 -> As of: May 26, 2021
A6: Provider Name: | B6: GHI Company
A7: FM Solution/Service Package Name: | B7: GHI Audit Support and Internal Control Review Services
A8: FM Solution/Service Package Short Description: | B8: GHI offers audit readiness and internal control review services for Federal financial management operations and Core FS solutions. Our services include personnel specializing in Federal financial management and software to plan, monitor, and report audit readiness and internal control review activities, schedules, issues, and resolution status.
A9: Business View
A10: FFM Functions: Activities | B10: Indicator | C10: Additional Explanation
A11: =CONCATENATE('FFM-Functions-Activities'!B3,": ",'FFM-Functions-Activities'!D3) -> Budget Execution: Budget Setup and Maintenance | B11: INCL | C11: Included in scope of review
A12: =CONCATENATE('FFM-Functions-Activities'!B4,": ",'FFM-Functions-Activities'!D4) -> Budget Execution: Fund Allocation and Control | B12: INCL | C12: Included in scope of review
A13: =CONCATENATE('FFM-Functions-Activities'!B5,": ",'FFM-Functions-Activities'!D5) -> Budget Execution: Budgetary Reporting | B13: INCL | C13: Included in scope of review
A14: =CONCATENATE('FFM-Functions-Activities'!B6,": ",'FFM-Functions-Activities'!D6) -> Financial Asset Information Management: Financial Asset Information Processing - Property, Plant, and Equipment | B14: INCL | C14: Included in scope of review
A15: =CONCATENATE('FFM-Functions-Activities'!B7,": ",'FFM-Functions-Activities'!D7) -> Financial Asset Information Management: Financial Asset Information Processing - Loans | B15: EXCL/O | C15: Can be included in service scope for additional cost
A16: =CONCATENATE('FFM-Functions-Activities'!B8,": ",'FFM-Functions-Activities'!D8) -> Financial Asset Information Management: Financial Asset Information Processing - Heritage Assets and Stewardship Land | B16: EXCL/O | C16: Can be included in service scope for additional cost
A17: =CONCATENATE('FFM-Functions-Activities'!B9,": ",'FFM-Functions-Activities'!D9) -> Financial Asset Information Management: Financial Asset Information Processing - Federal Oil and Gas Resources | B17: EXCL/O | C17: Can be included in service scope for additional cost
A18: =CONCATENATE('FFM-Functions-Activities'!B10,": ",'FFM-Functions-Activities'!D10) -> Financial Asset Information Management: Financial Asset Information Processing - Other Federal Assets | B18: EXCL/O | C18: Can be included in service scope for additional cost
A19: =CONCATENATE('FFM-Functions-Activities'!B11,": ",'FFM-Functions-Activities'!D11) -> Financial Asset Information Management: Financial Asset Information Reporting | B19: INCL | C19: Included in scope of review
A20: =CONCATENATE('FFM-Functions-Activities'!B12,": ",'FFM-Functions-Activities'!D12) -> Payable Management: Payee Setup and Maintenance | B20: INCL | C20: Included in scope of review
A21: =CONCATENATE('FFM-Functions-Activities'!B13,": ",'FFM-Functions-Activities'!D13) -> Payable Management: Obligation Management | B21: INCL | C21: Included in scope of review
A22: =CONCATENATE('FFM-Functions-Activities'!B14,": ",'FFM-Functions-Activities'!D14) -> Payable Management: Payment Processing - Intragovernmental Payments | B22: INCL | C22: Included in scope of review
... A64: =CONCATENATE('FFM-Functions-Activities'!B56,": ",'FFM-Functions-Activities'!D56) -> Financial / Performance Reporting: Internal Control/Compliance Reviews | B64: INCL | C64: Service Customer must provide results of previous 2 years and any ongoing internal control and compliance reviews to be included in scope of review
A66: Asset View
A67: Service Delivery Resources: | B67: Technology | H67: Workforce | J67: Advisory | L67: Additional Explanation
A68: Cost Pools: | B68: Facilities | C68: Telecom-Network | D68: Hardware | E68: Software | F68: Internal Services | G68: Outside Services | H68: Internal Labor | I68: External Labor | J68: Internal Labor | K68: External Labor
A69: Service Delivery Layers and Towers: Sub-Towers
A70: SL0: Service Delivery Management
A71: IT Management: IT Management and Strategic Planning | B71: N/A | C71: N/A | D71: N/A | E71: N/A | F71: N/A | G71: N/A | H71: N/A | I71: N/A | J71: N/A | K71: N/A
A72: IT Management: Enterprise Architecture | B72: N/A | C72: N/A | D72: N/A | E72: N/A | F72: N/A | G72: N/A | H72: N/A | I72: N/A | J72: N/A | K72: N/A
A73: IT Management: IT Finance | B73: N/A | C73: N/A | D73: N/A | E73: N/A | F73: N/A | G73: N/A | H73: N/A | I73: N/A | J73: N/A | K73: N/A
A74: IT Management: IT Vendor Management | B74: N/A | C74: N/A | D74: N/A | E74: N/A | F74: N/A | G74: N/A | H74: N/A | I74: N/A | J74: N/A | K74: N/A
A75: IT Management: IT Human Capital Management | B75: N/A | C75: N/A | D75: N/A | E75: N/A | F75: N/A | G75: N/A | H75: N/A | I75: N/A | J75: N/A | K75: N/A
A76: IT Management: IT Personnel Travel | B76: N/A | C76: N/A | D76: N/A | E76: N/A | F76: N/A | G76: N/A | H76: N/A | I76: N/A | J76: N/A | K76: N/A
A77: Delivery: IT Service Management | B77: N/A | C77: N/A | D77: N/A | E77: N/A | F77: N/A | G77: N/A | H77: N/A | I77: N/A | J77: N/A | K77: N/A
A78: Delivery: Program, Product & Project Management | B78: N/A | C78: N/A | D78: N/A | E78: N/A | F78: N/A | G78: N/A | H78: N/A | I78: N/A | J78: N/A | K78: N/A
A79: Delivery: Client Management | B79: N/A | C79: N/A | D79: N/A | E79: N/A | F79: N/A | G79: N/A | H79: N/A | I79: N/A | J79: N/A | K79: N/A
A80: Delivery: Operations Center | B80: N/A | C80: N/A | D80: N/A | E80: N/A | F80: N/A | G80: N/A | H80: N/A | I80: N/A | J80: N/A | K80: N/A
A81: Delivery: IT Service Design and Improvement | B81: N/A | C81: N/A | D81: N/A | E81: N/A | F81: N/A | G81: N/A | H81: N/A | I81: N/A | J81: N/A | K81: N/A
A82: Security & Compliance: Security | B82: N/A | C82: N/A | D82: N/A | E82: N/A | F82: N/A | G82: N/A | H82: N/A | I82: N/A | J82: N/A | K82: N/A
... A92: Business Management: Business Personnel Travel | B92: N/A | C92: N/A | D92: N/A | E92: N/A | F92: INCL | G92: N/A | H92: INCL | I92: INCL | J92: N/A | K92: INCL
...

Sheet FFM-Functions-Activities
A1: PRE-DECISIONAL DRAFT (May 26, 2021) Any text in the ServiceActivityDescripton column noted in red indicates a proposed change from the standard previously released in February 2021. An official copy of the finalized version will be released in the summer of 2021.
A2: FunctionAreaID | B2: ServiceFunctionName | C2: ServiceActivityID | D2: ServiceActivityName | E2: ServiceActivityDescription
A3: FFM.010 | B3: Budget Execution | C3: FFM.010.010 | D3: Budget Setup and Maintenance | E3: Establish and maintain budgetary resource reporting attributes; Receive agency spend and operating plan; Establish and maintain appropriated fund subdivisions before any of the appropriated funds are expended, according to OMB apportionments and agency spend and operating plan; Set up the funds control structure, levels, and accounting segments; Record the Treasury Accounting Fund Symbol (TAFS)/ Program/ Project/ Activity (PPA) information and organizational information for allotment and allocation; Includes setting up direct, reimbursable, revolving, contract, borrowing, financing, liquidating, advanced appropriation, anticipated collections, and non-expenditure transfer funds; Includes recording appropriation warrants, apportionments, allotments, allowances, allocations, reapportionments, transfer allocations, continuing resolutions, rescissions, and reprogramming actions
A4: FFM.010 | B4: Budget Execution | C4: FFM.010.020 | D4: Fund Allocation and Control | E4: Implement controls designed to detect or prevent overspending for defined accounting segments; Execute statutory limitation control of funds restricting obligations and expenditures to amounts authorized by law; Execute administrative control of funds restricting obligation and expenditure from each account to the lower of the amount apportioned by OMB or the amount available for obligation and/or expenditure; Update funds control rules
A5: FFM.010 | B5: Budget Execution | C5: FFM.010.030 | D5: Budgetary Reporting | E5: Perform budgetary resource and budget execution analysis; Provide cumulative budgetary resource and budget execution reports to governing financial management authorities (e.g. OMB); Provide reports of impacts from unusual events, such as sequestration, rescission, and deferrals; Provide reports on Antideficiency Act violations; Includes generating SF-132 and SF-133 and providing information needed for Budget Formulation; Verify required budgetary reports (e.g., SF-133) and general ledger account balances can be traced to appropriate supporting documentation
A6: FFM.020 | B6: Financial Asset Information Management | C6: FFM.020.010 | D6: Financial Asset Information Processing - Property, Plant, and Equipment | E6: Record financial asset type, category, value, and value adjustments (e.g., depreciation, impairment); Includes financial asset information processing for purchase and lease transactions, inventory, constructed assets and software
A7: FFM.020 | B7: Financial Asset Information Management | C7: FFM.020.020 | D7: Financial Asset Information Processing - Loans | E7: Record financial asset type, category, value, and value adjustments (e.g., allowance for uncollectible amounts, subsidy allowance)
A8: FFM.020 | B8: Financial Asset Information Management | C8: FFM.020.030 | D8: Financial Asset Information Processing - Heritage Assets and Stewardship Land | E8: Record financial asset type, category, value, and value adjustments (e.g., depreciation, impairment)
A9: FFM.020 | B9: Financial Asset Information Management | C9: FFM.020.040 | D9: Financial Asset Information Processing - Federal Oil and Gas Resources | E9: Record financial asset type, category, value, and value adjustments
A10: FFM.020 | B10: Financial Asset Information Management | C10: FFM.020.050 | D10: Financial Asset Information Processing - Other Federal Assets | E10: Record financial asset type, category, value, and value adjustments; Includes financial asset information processing for seized and forfeited assets and investments in Treasury securities
A11: FFM.020 | B11: Financial Asset Information Management | C11: FFM.020.060 | D11: Financial Asset Information Reporting | E11: Provide financial asset information (e.g., asset type, value) for financial reporting and reconciliation with information in the asset management systems
A12: FFM.030 | B12: Payable Management | C12: FFM.030.010 | D12: Payee Setup and Maintenance | E12: Establish and maintain federal and nonfederal payee information; Validate payee information against other payee information sources (e.g. SAM, Do Not Pay List)
A13: FFM.030 | B13: Payable Management | C13: FFM.030.020 | D13: Obligation Management | E13: Record commitments (if applicable); Record obligations for both procurement and non-procurement purchases; Includes decommitments/ modifications, liquidating commitments, deobligations/ modifications, and liquidating obligations; Includes capturing obligation information as required to support the Digital Accountability and Transparency Act of 2014 (DATA Act); Includes verifying the validity of the undelivered orders balance
... A56: FFM.110 | B56: Financial / Performance Reporting | C56: FFM.110.050 | D56: Internal Control/Compliance Reviews | E56: Implement standard internal control and compliance assurance procedures; Provide documentation to satisfy “Prepared By Client” requests from auditors; Prepare cycle memos; Provide sample information and documentation for compliance with other guidance, such as OMB Circular A-123; Record adjustments based on audit findings

Sheet Serv Delivery Layers
G1: Draft/Pre-Decisional
G2: This RFI (Request for Information) is issued solely for market research and planning purposes. The RFI does not constitute a solicitation or a commitment to a particular acquisition strategy. The RFI is intended to get industry feedback on the vision for the FM QSMO Marketplace, which includes core financial system and other financial management services and solutions. Nothing in this document should be construed as a final government decision upon which industry should take action and the RFI is subject to change. Treasury is not seeking proposals at this time and will not consider unsolicited proposals provided in response to the RFI. All information received in response to the RFI that is marked as proprietary will be handled accordingly. Responses to this notice are not offers and cannot be accepted by the Government to form a binding contract. Responders are solely responsible for all expenses associated with responding to the RFI.
B7: Service Delivery Layers and Resources
B8: As of: May 26, 2021
B40: It is anticipated that offerings in each of the FM QSMO Marketplace categories may include one or more of the following types of Service Delivery Resources: • Technology – the physical assets needed to deliver to FM solution/service • Workforce – the personnel that plan, build, implement, operate and/or deliver the FM solution/service on an on-going basis • Advisory – the personnel that advise, guide, consult and/or perform Independent Verification and Validation on an as-needed basis. It is also anticipated that offerings in each of the FM QSMO Marketplace categories may include one or more of the following types of Service Delivery Layers: • Service Delivery Layer 0 – components supporting the overall management of the FM solution/service and cross-Service Layer functions such as asset and configuration management, security and privacy assurance and audit, and Disaster Recovery (DR) and Continuity of Operations (COOP) management • Service Layers 1 and 2 – components such as hardware, operating system software, and storage, as well as the facilities they are housed in and the networks needed to connect these technologies (all together commonly referred to as the “infrastructure”) • Service Layers 3, 4, and 5 – components providing enterprise, middleware, or business application software, managing content and data, and providing technical support for the business applications • Service Layers 6 and 7 – components supporting business operations such as transaction processing, document or data pre-processing, business function guidance, data reporting, and data analyses.

Sheet Towers-SubTowers
C1: Draft/Pre-Decisional
C2: This RFI (Request for Information) is issued solely for market research and planning purposes. The RFI does not constitute a solicitation or a commitment to a particular acquisition strategy. The RFI is intended to get industry feedback on the vision for the FM QSMO Marketplace, which includes core financial system and other financial management services and solutions. Nothing in this document should be construed as a final government decision upon which industry should take action and the RFI is subject to change. Treasury is not seeking proposals at this time and will not consider unsolicited proposals provided in response to the RFI. All information received in response to the RFI that is marked as proprietary will be handled accordingly. Responses to this notice are not offers and cannot be accepted by the Government to form a binding contract. Responders are solely responsible for all expenses associated with responding to the RFI.
A6: Towers-SubTowers
A7: =Overview!A4 -> As of: May 26, 2021 | C7: The high-level list and description of the commercial TBM Taxonomy Towers/Sub-Towers (https://higherlogicdownload.s3.amazonaws.com/TBMCOUNCIL/c15d372f-9951-46c8-9c3f-213c696401b6/UploadedImages/TBM_Taxonomy_V4_0.pdf) has been augmented with government-defined extensions to fully account for other anticipated service delivery components and costs not explicitly addressed in the commercial TBM Tower/Sub-Tower descriptions.
A8: Light Blue = Commercial TBM v4 | C8: Gold = Federal Government Extension
A9: Tower ID | B9: Tower Name | C9: Sub-Tower ID | D9: Tower/Sub-Tower Name | E9: Tower/Sub-Tower Description
A10: 0.1 | B10: IT Management | E10: The IT Management tower includes the costs to manage, administer & plan IT for the enterprise. It includes executive management, strategic management, enterprise architecture, IT finance, and vendor management.
A11: 0.1 | B11: IT Management | C11: 0.1.1 | D11: IT Management & Strategic Planning | E11: IT management and administration resources; typically CIO, senior IT leaders and administrative support including centralized IT strategy and planning.
A12: 0.1 | B12: IT Management | C12: 0.1.2 | D12: Enterprise Architecture | E12: Enterprise architecture services including business, information, application and technical architecture to drive standardization, integration and efficiency among business technology solutions.
A13: 0.1 | B13: IT Management | C13: 0.1.3 | D13: IT Finance | E13: Resources involved in the planning, budgeting, spend management and chargeback of IT expenditures and the costing of IT products and services.
A14: 0.1 | B14: IT Management | C14: 0.1.4 | D14: IT Vendor Management | E14: Resources involved in the selection, contract management, oversight, performance management and general delivery of IT services by 3rd party vendors and external service providers.
A15: 0.1 | B15: IT Management | C15: 0.1.5 | D15: IT Human Capital Management | E15: Resources involved in the acquisition, development, performance management, compensation, and separation of IT personnel. Included are initial and periodic personnel background investigations and drug testing, as well as training on organizational policies and procedures.
A16: 0.1 | B16: IT Management | C16: 0.1.6 | D16: IT Personnel Travel | E16: Any IT personnel travel related to official work.
A17: 0.2 | B17: Delivery | E17: The delivery tower includes the costs to monitor, support, manage, and run IT operations for the enterprise and includes the IT Service Management (ITSM) functions.
A18: 0.2 | B18: Delivery | C18: 0.2.1 | D18: IT Service Management | E18: Resources involved with the incident, problem and change management activities as part of the IT Service Management process (excludes the Tier 1 help desk).
A19: 0.2 | B19: Delivery | C19: 0.2.2 | D19: IT Program, Product & Project Management | E19: Resources involved with managing and supporting IT related projects and/or continuous product development (e.g. Agile) across business and IT-driven initiatives.
A20: 0.2 | B20: Delivery | C20: 0.2.3 | D20: Client Management | E20: Resources or “account managers” aligned with the lines of business to understand business needs, communicate IT products, services and status of IT projects.
A21: 0.2 | B21: Delivery | C21: 0.2.4 | D21: Operations Center | E21: Centralized IT Operations Center resources including monitoring and intervention e.g., NOC (network operations center), GOC (global operations center).
A22: 0.2 | B22: Delivery | C22: 0.2.5 | D22: IT Service Design and Improvement | E22: Resources involved with designing, monitoring, reporting, and improving services, including the associated service catalogue, service measures, and service agreements.
A23: 0.3 | B23: Security & Compliance | E23: The Security & Compliance tower includes service costs related to IT security compliance and disaster recovery. The scope includes costs to define, establish, enforce, and measure security, compliance, and disaster recovery readiness for the enterprise.
A24: 0.3 | B24: Security & Compliance | C24: 0.3.1 | D24: Security | E24: IT Security resources setting policy, establishing process & means, measuring compliance and responding to security breaches and providing real-time operational security such as vulnerability scanning, managing firewalls, intrusion prevention systems, and security information and event management (SIEM). Optional Level 3 categories include: Cyber Security. The implementation actions defined by security policies (e.g. mitigating security breaches by applying patches) are not included in the Security sub-tower and are part of the respective towers where the actions take place (e.g. Compute, Storage, Network).
A25: 0.3 | B25: Security & Compliance | C25: 0.3.2 | D25: Compliance | E25: IT Compliance resources setting policy, establishing controls and measuring compliance to relevant legal and compliance requirements. Optional Level 3 categories include: Data Privacy. The implementation actions defined by Compliance policy (e.g. implementing controls like multi-factor authentication) are not included in the Compliance subtower and are part of the respective towers where the actions take place (e.g. Compute, Storage, Network, Application, End User).
A26: 0.3 | B26: Security & Compliance | C26: 0.3.3 | D26: Disaster Recovery | E26: IT Disaster Recovery resources setting DR policy, establishing process & means, dedicated failover facilities, performing DR testing. NOTE: DR designated equipment is included directly in its own sub-tower (e.g., extra servers for DR are included in Compute tower, etc.). The implementation actions defined by Disaster Recovery policy (e.g. building DR servers) are not included in the Disaster & Recovery sub-tower and are part of the respective towers where the actions take place (e.g. Compute, Storage, Network).
A27: 0.3 | B27: Security & Compliance | C27: 0.3.4 | D27: Federal Records Mgmt | E27: Resources establishing process, means and controls for ensuring compliance with the Federal Government's policies and procedures for creating, maintaining, and disposing of Federal electronic and digitized paper records.
A28: 1.1 | B28: Data Center | E28: Data Centers are purpose-built facilities to securely house computer equipment. Data Centers provide racks/cabinets & cabling, clean & redundant power, data connectivity, environmental controls including temperature, humidity and fire suppression, physical security and the people to run and operate the facility and its infrastructure.
A29: 1.1 | B29: Data Center | C29: 1.1.1 | D29: Enterprise Data Center | E29: Purpose-built data center facilities that house and protect critical IT equipment including the space, power, environment controls, racks, cabling and "smart hand" support.
A30: 1.1 | B30: Data Center | C30: 1.1.2 | D30: Other IT Facilities | E30: Computer rooms and MDF/IDF/telco closets that house IT equipment in corporate headquarters, call centers or other general purpose office buildings.
A31: 1.1 | B31: Data Center | C31: 1.1.3 | D31: IT Transport Vehicles & Equipment | E31: Vehicles and equipment for transport of IT personnel and assets.
A32: 1.1 | B32: Data Center | C32: 1.1.4 | D32: IT Office Furniture & Supplies | E32: Furniture and supplies for IT offices.
A33: 1.2 | B33: Network | E33: Network includes the data and voice equipment along with the transport methods to connect systems and people and to enable people to converse. Networks provide core connectivity within the enterprise data centers as well as connectivity to and access within office building and remote locations.
A34: 1.2 | B34: Network | C34: 1.2.1 | D34: LAN/WAN | E34: Physical and wireless local area network connecting equipment within the core data centers and connecting end users in office working areas to the organization's broader networks. Wide area network equipment, labor and support services directly connecting data centers, offices and third parties (excludes telecom and communication services). Optional Level 3 categories include: LAN, WAN.
A35: 1.2 | B35: Network | C35: 1.2.2 | D35: Voice | E35: Voice resources which enable or distribute voice services through on premise equipment including PBX, VoIP, voicemail and handsets (excludes telecom and communication services).
A36: 1.2 | B36: Network | C36: 1.2.3 | D36: Transport | E36: Data network circuits and associated access facilities and services; includes dedicated and virtual data networks and internet access. Also includes usage associated with mobility and other data transit based on usage billing. Voice network circuits and associated access facilities and services. Also includes usage associated with standard telephone calls and 800 number service. Both voice and data transport may include terrestrial and non-terrestrial (e.g., satellite) technologies. Optional Level 3 categories include: Data, Voice.
A37: 2.1 | B37: Compute | E37: Compute refers to both general and special-purpose devices and software that are programmed to carry out a set of arithmetic or logical operations. In essence, it provides the “brains” to process application and user requests. Compute includes a wide range of physical and virtual servers differentiated by platform and operating system. The Compute tower should include all direct hardware, software, labor and outside service costs.
A38: 2.1 | B38: Compute | C38: 2.1.1 | D38: Servers | E38: Physical and virtual servers running a version of Microsoft's Windows Server or the Linux operating system; includes hardware, software, labor and support services. Optional Level 3 categories include: Windows, Linux and Public Cloud Compute.
A39: 2.1 | B39: Compute | C39: 2.1.2 | D39: Unix | E39: Servers running vendor-specific, proprietary Unix operating systems (e.g., IBM AIX, Sun Solaris, HP UX); includes hardware, software, labor and support services.
A40: 2.1 | B40: Compute | C40: 2.1.3 | D40: Midrange | E40: Servers running IBM AS/400 platform including hardware, software, labor and support services.
A41: 2.1 | B41: Compute | C41: 2.1.4 | D41: Converged Infrastructure | E41: Purpose-built appliances that provide compute, storage and network capabilities in one box.
A42: 2.1 | B42: Compute | C42: 2.1.5 | D42: Mainframe | E42: Traditional mainframe computers and operations running legacy operating systems.
A43: 2.1 | B43: Compute | C43: 2.1.6 | D43: High Performance Computing | E43: Purpose-built servers that use parallel processing and clustering for running advanced application programs and for solving complex computational problems efficiently, reliably and quickly.
...

Sheet Service Components List
C1: Draft/Pre-Decisional
C2: This RFI (Request for Information) is issued solely for market research and planning purposes. The RFI does not constitute a solicitation or a commitment to a particular acquisition strategy. The RFI is intended to get industry feedback on the vision for the FM QSMO Marketplace, which includes core financial system and other financial management services and solutions. Nothing in this document should be construed as a final government decision upon which industry should take action and the RFI is subject to change. Treasury is not seeking proposals at this time and will not consider unsolicited proposals provided in response to the RFI. All information received in response to the RFI that is marked as proprietary will be handled accordingly. Responses to this notice are not offers and cannot be accepted by the Government to form a binding contract. Responders are solely responsible for all expenses associated with responding to the RFI.
A3: Service Components List
A4: ='Cover Page'!A16 -> As of: May 26, 2021
A6: Service Component ID | B6: Service Component Name | C6: Service Component Notes | D6: Service Layer | E6: Service Type | F6: Tower ID | G6: Tower Name | H6: Sub-Tower ID | I6: Sub-Tower Name | J6: Cost Pool ID | K6: Cost Pool Name | L6: Sub-Cost Pool ID | M6: Sub-Cost Pool Name | N6: ITIL Practice Area: Practice
A7: 0.01.01 | B7: Executive Management Personnel - Government | C7: Includes pay and other benefits | D7: SL0: Service Delivery Management | E7: Workforce | F7: 0.1 | G7: IT Management | H7: 0.1.1 | I7: IT Management & Strategic Planning | J7: 2.1 | K7: Internal Labor | L7: 2.1.1 | M7: Expense | N7: General Management: Project Management; General Management: Relationship Management
